<?xml version="1.0" ?>
<!-- =================================================================================== -->
<!-- |    This document was autogenerated by xacro from models/ApolloRobot.urdf.xacro  | -->
<!-- |    EDITING THIS FILE BY HAND IS NOT RECOMMENDED                                 | -->
<!-- =================================================================================== -->
<robot name="apollo_robot">
  <!-- offsets from Kuka joint convention to SL  -->
  <!-- offsets from Kuka joint convention to SL  -->
  <!-- offsets from Kuka joint convention to SL  -->
  <!-- offsets from Kuka joint convention to SL  -->
  <!-- Manually measured position -->
  <!--xacro:property name="XTIONFromNeckXYZ" value="-0.019 -0.08762 -0.2067" /-->
  <!--xacro:property name="XTIONFromNeckRPY" value="1.134 0.0 0.0" /-->
  <!-- Best transform so far from data collected August14th - without even minimal table pose optimization -->
  <!-- xacro:property name="XTIONFromNeckXYZ" value="-0.008368 -0.102347 -0.207270" /-->
  <!-- xacro:property name="XTIONFromNeckRPY" value="1.108573 -0.001902 -0.039201" /-->
  <material name="DarpaGrey">
    <color rgba="0.9 0.9 0.9 1.0"/>
  </material>
  <material name="DarpaBlue">
    <color rgba="0.0 0.5 0.5 1.0"/>
  </material>
  <link name="world"/>
  <link name="BASE">
    <inertial>
      <origin rpy="0 0 0" xyz="0 0 0"/>
      <mass value="1.0"/>
      <inertia ixx="1.0" ixy="0.0" ixz="0.0" iyy="100.0" iyz="0.0" izz="1.0"/>
    </inertial>
    <visual>
      <material name="DarpaGrey"/>
      <origin rpy="0 0 3.14159265359" xyz="0 0 -1.400"/>
      <geometry>
        <mesh filename="meshes/stand.stl"/>
      </geometry>
    </visual>
    <collision>
      <origin rpy="0 0 3.14159265359" xyz="0 0 -1.400"/>
      <geometry>
        <mesh filename="meshes/collision/stand.stl"/>
      </geometry>
    </collision>
  </link>
  <joint name="fixedJoint" type="fixed">
    <parent link="world"/>
    <child link="BASE"/>
    <!--origin xyz="0 0.2 1.305" rpy="0 0 ${PI}"/-->
    <origin rpy="0 0 3.14159265359" xyz="0 0 1.400"/>
  </joint>
  <!-- joint between {parent} and arm_0_link -->
  <joint name="L_BASE" type="fixed">
    <origin rpy="0 0 1.0471975512" xyz="0 0 0"/>
    <parent link="BASE"/>
    <child link="L_COLLARBONE"/>
  </joint>
  <link name="L_COLLARBONE">
    <inertial>
      <origin rpy="0 0 0" xyz="0 0.06813 0"/>
      <mass value="1.0"/>
      <inertia ixx="0.01" ixy="0" ixz="0" iyy="0.01" iyz="0" izz="0.01"/>
    </inertial>
    <visual>
      <material name="DarpaGrey"/>
      <origin rpy="0 0 0" xyz="0 0.06813 0"/>
      <geometry>
        <mesh filename="meshes/lbr0.stl"/>
      </geometry>
    </visual>
    <collision>
      <origin rpy="0 0 0" xyz="0 0.06813 0"/>
      <geometry>
        <mesh filename="meshes/collision/lbr0_smpl.stl"/>
      </geometry>
    </collision>
  </link>
  <!-- joint between arm_0_link and arm_1_link -->
  <joint name="L_SFE" type="revolute">
    <origin rpy="-1.57079632679 -0.0 0" xyz="0 0.16813 0"/>
    <!--origin xyz="0 0.16 0" rpy="-${PI/2.0} ${reflect*-SFE_offset} 0"/-->
    <parent link="L_COLLARBONE"/>
    <child link="L_SHOULDER"/>
    <axis xyz="0 0 -1"/>
    <dynamics damping="0"/>
    <limit effort="200" lower="-2.96" upper="2.96" velocity="1.9634"/>
  </joint>
  <link name="L_SHOULDER">
    <inertial>
      <origin rpy="0 0 0" xyz="0 0 0.018"/>
      <mass value="5.9907"/>
      <inertia ixx="0.01" ixy="0" ixz="0" iyy="0.01" iyz="0" izz="0.01"/>
    </inertial>
    <visual>
      <material name="DarpaGrey"/>
      <origin rpy="0 0 1.57079632679" xyz="0 0 0.018"/>
      <geometry>
        <mesh filename="meshes/lbr1.stl"/>
      </geometry>
    </visual>
    <collision>
      <origin rpy="0 0 1.57079632679" xyz="0 0 0.018"/>
      <geometry>
        <mesh filename="meshes/collision/lbr1_smpl.stl"/>
      </geometry>
    </collision>
  </link>
  <!-- joint between arm_1_link and arm_2_link -->
  <joint name="L_SAA" type="revolute">
    <!--origin xyz="0 0 0.2" rpy="${PI/2.0} ${PI/2.0 - reflect*SAA_offset} ${PI/2.0}"/-->
    <origin rpy="1.57079632679 3.14149632679 1.57079632679" xyz="0 0 0.2105"/>
    <parent link="L_SHOULDER"/>
    <child link="L_UPPER_ARM_IN_SHOULDER"/>
    <axis xyz="0 0 -1"/>
    <dynamics damping="0"/>
    <limit effort="200" lower="-3.1" upper="-0.1" velocity="1.9634"/>
  </joint>
  <link name="L_UPPER_ARM_IN_SHOULDER">
    <inertial>
      <origin rpy="0 0 0" xyz="0 0 0"/>
      <mass value="5.734939"/>
      <inertia ixx="0.03" ixy="0" ixz="0" iyy="0.03" iyz="0" izz="0.03"/>
    </inertial>
    <visual>
      <material name="DarpaGrey"/>
      <origin rpy="0 0 1.57079632679" xyz="0 0 0"/>
      <geometry>
        <mesh filename="meshes/lbr2.stl"/>
      </geometry>
    </visual>
    <collision>
      <origin rpy="0 0 1.57079632679" xyz="0 0 0"/>
      <geometry>
        <mesh filename="meshes/collision/lbr2_smpl.stl"/>
      </geometry>
    </collision>
  </link>
  <!-- joint between arm_2_link and arm_3_link -->
  <joint name="L_HR" type="revolute">
    <origin rpy="-1.57079632679  -0.523596326795 1.57079632679" xyz="-0.2 0 0"/>
    <parent link="L_UPPER_ARM_IN_SHOULDER"/>
    <child link="L_UPPER_ARM"/>
    <axis xyz="0 0 -1"/>
    <dynamics damping="0"/>
    <limit effort="100" lower="-1.9" upper="4.0" velocity="1.9634"/>
  </joint>
  <link name="L_UPPER_ARM">
    <inertial>
      <origin rpy="0 0 0" xyz="0 0 0.008"/>
      <mass value="4.214668"/>
      <inertia ixx="0.03" ixy="0" ixz="0" iyy="0.03" iyz="0" izz="0.03"/>
    </inertial>
    <visual>
      <material name="DarpaGrey"/>
      <origin rpy="0 0 1.57079632679" xyz="0 0 0.008"/>
      <geometry>
        <mesh filename="meshes/lbr3.stl"/>
      </geometry>
    </visual>
    <collision>
      <origin rpy="0 0 1.57079632679" xyz="0 0 0.008"/>
      <geometry>
        <mesh filename="meshes/collision/lbr3_smpl.stl"/>
      </geometry>
    </collision>
  </link>
  <!-- joint between arm_3_link and arm_4_link -->
  <joint name="L_EB" type="revolute">
    <origin rpy="-1.57079632679 -1.57079632679 1.57079632679" xyz="0 0 0.2"/>
    <parent link="L_UPPER_ARM"/>
    <child link="L_FOREARM"/>
    <axis xyz="0 0 -1"/>
    <dynamics damping="0"/>
    <limit effort="100" lower="-2.09" upper="2.09" velocity="1.9634"/>
  </joint>
  <link name="L_FOREARM">
    <inertial>
      <origin rpy="0 0 0" xyz="0 0 0"/>
      <mass value="3.669819"/>
      <inertia ixx="0.03" ixy="0" ixz="0" iyy="0.03" iyz="0" izz="0.03"/>
    </inertial>
    <visual>
      <material name="DarpaGrey"/>
      <origin rpy="0 0 1.57079632679" xyz="0 0 0"/>
      <geometry>
        <mesh filename="meshes/lbr4.stl"/>
      </geometry>
    </visual>
    <collision>
      <origin rpy="0 0 1.57079632679" xyz="0 0 0"/>
      <geometry>
        <mesh filename="meshes/collision/lbr4_smpl.stl"/>
      </geometry>
    </collision>
  </link>
  <!-- joint between arm_4_link and arm_5_link -->
  <joint name="L_WR" type="revolute">
    <origin rpy="1.57079632679 3.14149632679 1.57079632679" xyz="0.2 0 0"/>
    <parent link="L_FOREARM"/>
    <child link="L_UPPER_WRIST_YAW"/>
    <axis xyz="0 0 -1"/>
    <dynamics damping="0"/>
    <limit effort="100" lower="-3.1" upper="1.35" velocity="3.1415926"/>
  </joint>
  <link name="L_UPPER_WRIST_YAW">
    <inertial>
      <origin rpy="0 0 0" xyz="0 0 0.007"/>
      <mass value="2.313272"/>
      <inertia ixx="0.03" ixy="0" ixz="0" iyy="0.03" iyz="0" izz="0.03"/>
    </inertial>
    <visual>
      <material name="DarpaGrey"/>
      <origin rpy="0 0 1.57079632679" xyz="0 0 0.007"/>
      <geometry>
        <mesh filename="meshes/lbr5.stl"/>
      </geometry>
    </visual>
    <collision>
      <origin rpy="0 0 1.57079632679" xyz="0 0 0.007"/>
      <geometry>
        <mesh filename="meshes/collision/lbr5_smpl.stl"/>
      </geometry>
    </collision>
  </link>
  <!-- joint between arm_5_link and arm_6_link -->
  <joint name="L_WFE" type="revolute">
    <origin rpy="1.5708 -0.0 1.57079632679" xyz="0 0 0.19"/>
    <parent link="L_UPPER_WRIST_YAW"/>
    <child link="L_UPPER_WRIST_PITCH"/>
    <axis xyz="0 0 -1"/>
    <dynamics damping="0"/>
    <limit effort="30" lower="-2.09" upper="2.09" velocity="1.9634"/>
  </joint>
  <link name="L_UPPER_WRIST_PITCH">
    <inertial>
      <origin rpy="0 0 0" xyz="0 0 -0.046"/>
      <mass value="2.057856"/>
      <inertia ixx="0.01" ixy="0" ixz="0" iyy="0.01" iyz="0" izz="0.01"/>
    </inertial>
    <visual>
      <material name="DarpaGrey"/>
      <origin rpy="0 0 0" xyz="0 0 -0.046"/>
      <geometry>
        <mesh filename="meshes/lbr6.stl"/>
      </geometry>
    </visual>
    <collision>
      <origin rpy="0 0 0" xyz="0 0 -0.046"/>
      <geometry>
        <mesh filename="meshes/collision/lbr6_smpl.stl"/>
      </geometry>
    </collision>
  </link>
  <!-- joint between arm_6_link and arm_7_link -->
  <joint name="L_WAA" type="revolute">
    <origin rpy="-1.57079632679 -1.57079632679 0" xyz="0 0.048 0"/>
    <parent link="L_UPPER_WRIST_PITCH"/>
    <child link="L_LOWER_WRIST"/>
    <axis xyz="0 0 -1"/>
    <dynamics damping="0"/>
    <limit effort="30" lower="-2.96" upper="2.96" velocity="1.9634"/>
  </joint>
  <link name="L_LOWER_WRIST">
    <inertial>
      <origin rpy="0 0 0" xyz="0 0 0.009"/>
      <mass value="1.120198"/>
      <inertia ixx="0.01" ixy="0" ixz="0" iyy="0.01" iyz="0" izz="0.01"/>
    </inertial>
    <visual>
      <material name="DarpaGrey"/>
      <origin rpy="0 0 0" xyz="0 0 0.009"/>
      <geometry>
        <mesh filename="meshes/lbr7.stl"/>
      </geometry>
    </visual>
    <collision>
      <origin rpy="0 0 0" xyz="0 0 0.009"/>
      <geometry>
        <mesh filename="meshes/collision/lbr7_smpl.stl"/>
      </geometry>
    </collision>
  </link>
  <joint name="L_Arm_PalmBlueComponentJoint" type="fixed">
    <parent link="L_LOWER_WRIST"/>
    <child link="L_ARM_PALM"/>
    <origin rpy="0 0 3.14159265359" xyz="0 0 0.03"/>
  </joint>
  <link name="L_ARM_PALM">
    <inertial>
      <origin xyz="0 0 0.006"/>
      <mass value="0.00000001"/>
      <inertia ixx="0.00000001" ixy="0.00000001" ixz="-0.00000001" iyy="0.00000001" iyz="-0.00000001" izz="0.00000001"/>
    </inertial>
    <visual>
      <material name="DarpaGrey"/>
      <material name="DarpaBlue"/>
      <origin rpy="1.57079632679 0 0" xyz="0 0 0.006"/>
      <geometry>
        <mesh filename="meshes/wamLowerWristFTPalmLink7.stl"/>
      </geometry>
    </visual>
    <collision>
      <origin rpy="1.57079632679 0 0" xyz="0 0 0.006"/>
      <geometry>
        <mesh filename="meshes/collision/wamLowerWristFTPalmLink7_smpl.stl"/>
      </geometry>
    </collision>
  </link>
</robot>
