  <joint name="disk_joint_disk_number" type="prismatic">
    <parent link="planeLink"/>
    <child link="disk_link_disk_number"/>
    <limit effort="1000" lower="-10" upper="10" velocity="100000"/>
    <axis xyz="0 0 1"/>
    <origin rpy="0 0 0" xyz="x_position y_position -0.05"/>
  </joint>
  <link name="disk_link_disk_number">
    <contact>
        <lateral_friction value="1.0"/>
        <restitution value="0.0"/>
    </contact>
    <inertial>
      <origin rpy="0 0 0" xyz="0 0 0"/>
       <mass value="1.0"/>
       <inertia ixx="0" ixy="0" ixz="0" iyy="0" iyz="0" izz="0"/>
    </inertial>
    <collision>
      <origin rpy="0 0 0" xyz="0 0 0"/>
      <geometry>
        <box size="0.1 0.1 0.1"/>
      </geometry>
      <material name="white">
        <color rgba="1 1 1 1"/>
      </material>
    </collision>
    <visual>
      <origin rpy="0 0 0" xyz="0 0 0"/>
      <geometry>
        <box size="0.1 0.1 0.1"/>
      </geometry>
      <material name="white">
        <color rgba="1 1 1 1"/>
      </material>
    </visual>
  </link>
