<?xml version="1.0" ?>
<!-- =================================================================================== -->
<!-- |    This document was autogenerated by xacro from plane_with_restitution.urdf.xacro | -->
<!-- |    EDITING THIS FILE BY HAND IS NOT RECOMMENDED                                 | -->
<!-- =================================================================================== -->
<robot name="plane">
  <link name="planeLink">
    <contact>
      <lateral_friction value="1.0"/>
      <restitution value="0.0"/>
    </contact>
    <inertial>
      <origin rpy="0 0 0" xyz="0 0 0"/>
      <mass value=".0"/>
      <inertia ixx="0" ixy="0" ixz="0" iyy="0" iyz="0" izz="0"/>
    </inertial>
    <visual>
      <origin rpy="0 0 0" xyz="0.85 -0.1 -0.12"/>
      <geometry>
        <box size="2 0.5 0.04"/>
      </geometry>
      <material name="white">
        <color rgba="1 1 1 1"/>
      </material>
    </visual>
    <collision>
      <origin rpy="0 0 0" xyz="0.85 -0.1 -0.12"/>
      <geometry>
        <box size="2 0.5 0.04"/>
      </geometry>
    </collision>
  </link>
    <joint name="disk_joint_000" type="prismatic">
    <parent link="planeLink"/>
    <child link="disk_link_000"/>
    <limit effort="1000" lower="-10" upper="10" velocity="100000"/>
    <axis xyz="0 0 1"/>
    <origin rpy="0 0 0" xyz="0.2310104599667308 0.050647763888851983 -0.05"/>
  </joint>
  <link name="disk_link_000">
    <contact>
        <lateral_friction value="1.0"/>
        <restitution value="0.0"/>
    </contact>
    <inertial>
      <origin rpy="0 0 0" xyz="0 0 0"/>
       <mass value="1.0"/>
       <inertia ixx="0" ixy="0" ixz="0" iyy="0" iyz="0" izz="0"/>
    </inertial>
    <collision>
      <origin rpy="0 0 0" xyz="0 0 0"/>
      <geometry>
        <box size="0.1 0.1 0.1"/>
      </geometry>
      <material name="white">
        <color rgba="1 1 1 1"/>
      </material>
    </collision>
    <visual>
      <origin rpy="0 0 0" xyz="0 0 0"/>
      <geometry>
        <box size="0.1 0.1 0.1"/>
      </geometry>
      <material name="white">
        <color rgba="1 1 1 1"/>
      </material>
    </visual>
  </link>
  <joint name="disk_joint_001" type="prismatic">
    <parent link="planeLink"/>
    <child link="disk_link_001"/>
    <limit effort="1000" lower="-10" upper="10" velocity="100000"/>
    <axis xyz="0 0 1"/>
    <origin rpy="0 0 0" xyz="0.2969591136928226 -0.09700729740518442 -0.05"/>
  </joint>
  <link name="disk_link_001">
    <contact>
        <lateral_friction value="1.0"/>
        <restitution value="0.0"/>
    </contact>
    <inertial>
      <origin rpy="0 0 0" xyz="0 0 0"/>
       <mass value="1.0"/>
       <inertia ixx="0" ixy="0" ixz="0" iyy="0" iyz="0" izz="0"/>
    </inertial>
    <collision>
      <origin rpy="0 0 0" xyz="0 0 0"/>
      <geometry>
        <box size="0.1 0.1 0.1"/>
      </geometry>
      <material name="white">
        <color rgba="1 1 1 1"/>
      </material>
    </collision>
    <visual>
      <origin rpy="0 0 0" xyz="0 0 0"/>
      <geometry>
        <box size="0.1 0.1 0.1"/>
      </geometry>
      <material name="white">
        <color rgba="1 1 1 1"/>
      </material>
    </visual>
  </link>
  <joint name="disk_joint_002" type="prismatic">
    <parent link="planeLink"/>
    <child link="disk_link_002"/>
    <limit effort="1000" lower="-10" upper="10" velocity="100000"/>
    <axis xyz="0 0 1"/>
    <origin rpy="0 0 0" xyz="0.390574950430909 0.015025331780004255 -0.05"/>
  </joint>
  <link name="disk_link_002">
    <contact>
        <lateral_friction value="1.0"/>
        <restitution value="0.0"/>
    </contact>
    <inertial>
      <origin rpy="0 0 0" xyz="0 0 0"/>
       <mass value="1.0"/>
       <inertia ixx="0" ixy="0" ixz="0" iyy="0" iyz="0" izz="0"/>
    </inertial>
    <collision>
      <origin rpy="0 0 0" xyz="0 0 0"/>
      <geometry>
        <box size="0.1 0.1 0.1"/>
      </geometry>
      <material name="white">
        <color rgba="1 1 1 1"/>
      </material>
    </collision>
    <visual>
      <origin rpy="0 0 0" xyz="0 0 0"/>
      <geometry>
        <box size="0.1 0.1 0.1"/>
      </geometry>
      <material name="white">
        <color rgba="1 1 1 1"/>
      </material>
    </visual>
  </link>
  <joint name="disk_joint_003" type="prismatic">
    <parent link="planeLink"/>
    <child link="disk_link_003"/>
    <limit effort="1000" lower="-10" upper="10" velocity="100000"/>
    <axis xyz="0 0 1"/>
    <origin rpy="0 0 0" xyz="0.4709467151014552 -0.15623301192813455 -0.05"/>
  </joint>
  <link name="disk_link_003">
    <contact>
        <lateral_friction value="1.0"/>
        <restitution value="0.0"/>
    </contact>
    <inertial>
      <origin rpy="0 0 0" xyz="0 0 0"/>
       <mass value="1.0"/>
       <inertia ixx="0" ixy="0" ixz="0" iyy="0" iyz="0" izz="0"/>
    </inertial>
    <collision>
      <origin rpy="0 0 0" xyz="0 0 0"/>
      <geometry>
        <box size="0.1 0.1 0.1"/>
      </geometry>
      <material name="white">
        <color rgba="1 1 1 1"/>
      </material>
    </collision>
    <visual>
      <origin rpy="0 0 0" xyz="0 0 0"/>
      <geometry>
        <box size="0.1 0.1 0.1"/>
      </geometry>
      <material name="white">
        <color rgba="1 1 1 1"/>
      </material>
    </visual>
  </link>
  <joint name="disk_joint_004" type="prismatic">
    <parent link="planeLink"/>
    <child link="disk_link_004"/>
    <limit effort="1000" lower="-10" upper="10" velocity="100000"/>
    <axis xyz="0 0 1"/>
    <origin rpy="0 0 0" xyz="0.537315868208263 -0.010442785155386712 -0.05"/>
  </joint>
  <link name="disk_link_004">
    <contact>
        <lateral_friction value="1.0"/>
        <restitution value="0.0"/>
    </contact>
    <inertial>
      <origin rpy="0 0 0" xyz="0 0 0"/>
       <mass value="1.0"/>
       <inertia ixx="0" ixy="0" ixz="0" iyy="0" iyz="0" izz="0"/>
    </inertial>
    <collision>
      <origin rpy="0 0 0" xyz="0 0 0"/>
      <geometry>
        <box size="0.1 0.1 0.1"/>
      </geometry>
      <material name="white">
        <color rgba="1 1 1 1"/>
      </material>
    </collision>
    <visual>
      <origin rpy="0 0 0" xyz="0 0 0"/>
      <geometry>
        <box size="0.1 0.1 0.1"/>
      </geometry>
      <material name="white">
        <color rgba="1 1 1 1"/>
      </material>
    </visual>
  </link>
  <joint name="disk_joint_005" type="prismatic">
    <parent link="planeLink"/>
    <child link="disk_link_005"/>
    <limit effort="1000" lower="-10" upper="10" velocity="100000"/>
    <axis xyz="0 0 1"/>
    <origin rpy="0 0 0" xyz="0.6284558666370316 -0.18540581361519115 -0.05"/>
  </joint>
  <link name="disk_link_005">
    <contact>
        <lateral_friction value="1.0"/>
        <restitution value="0.0"/>
    </contact>
    <inertial>
      <origin rpy="0 0 0" xyz="0 0 0"/>
       <mass value="1.0"/>
       <inertia ixx="0" ixy="0" ixz="0" iyy="0" iyz="0" izz="0"/>
    </inertial>
    <collision>
      <origin rpy="0 0 0" xyz="0 0 0"/>
      <geometry>
        <box size="0.1 0.1 0.1"/>
      </geometry>
      <material name="white">
        <color rgba="1 1 1 1"/>
      </material>
    </collision>
    <visual>
      <origin rpy="0 0 0" xyz="0 0 0"/>
      <geometry>
        <box size="0.1 0.1 0.1"/>
      </geometry>
      <material name="white">
        <color rgba="1 1 1 1"/>
      </material>
    </visual>
  </link>
  <joint name="disk_joint_006" type="prismatic">
    <parent link="planeLink"/>
    <child link="disk_link_006"/>
    <limit effort="1000" lower="-10" upper="10" velocity="100000"/>
    <axis xyz="0 0 1"/>
    <origin rpy="0 0 0" xyz="0.6737209751410542 -0.02453396936138319 -0.05"/>
  </joint>
  <link name="disk_link_006">
    <contact>
        <lateral_friction value="1.0"/>
        <restitution value="0.0"/>
    </contact>
    <inertial>
      <origin rpy="0 0 0" xyz="0 0 0"/>
       <mass value="1.0"/>
       <inertia ixx="0" ixy="0" ixz="0" iyy="0" iyz="0" izz="0"/>
    </inertial>
    <collision>
      <origin rpy="0 0 0" xyz="0 0 0"/>
      <geometry>
        <box size="0.1 0.1 0.1"/>
      </geometry>
      <material name="white">
        <color rgba="1 1 1 1"/>
      </material>
    </collision>
    <visual>
      <origin rpy="0 0 0" xyz="0 0 0"/>
      <geometry>
        <box size="0.1 0.1 0.1"/>
      </geometry>
      <material name="white">
        <color rgba="1 1 1 1"/>
      </material>
    </visual>
  </link>
  <joint name="disk_joint_007" type="prismatic">
    <parent link="planeLink"/>
    <child link="disk_link_007"/>
    <limit effort="1000" lower="-10" upper="10" velocity="100000"/>
    <axis xyz="0 0 1"/>
    <origin rpy="0 0 0" xyz="0.7665436551221169 -0.19177342412637377 -0.05"/>
  </joint>
  <link name="disk_link_007">
    <contact>
        <lateral_friction value="1.0"/>
        <restitution value="0.0"/>
    </contact>
    <inertial>
      <origin rpy="0 0 0" xyz="0 0 0"/>
       <mass value="1.0"/>
       <inertia ixx="0" ixy="0" ixz="0" iyy="0" iyz="0" izz="0"/>
    </inertial>
    <collision>
      <origin rpy="0 0 0" xyz="0 0 0"/>
      <geometry>
        <box size="0.1 0.1 0.1"/>
      </geometry>
      <material name="white">
        <color rgba="1 1 1 1"/>
      </material>
    </collision>
    <visual>
      <origin rpy="0 0 0" xyz="0 0 0"/>
      <geometry>
        <box size="0.1 0.1 0.1"/>
      </geometry>
      <material name="white">
        <color rgba="1 1 1 1"/>
      </material>
    </visual>
  </link>
  <joint name="disk_joint_008" type="prismatic">
    <parent link="planeLink"/>
    <child link="disk_link_008"/>
    <limit effort="1000" lower="-10" upper="10" velocity="100000"/>
    <axis xyz="0 0 1"/>
    <origin rpy="0 0 0" xyz="0.8223524747499102 -0.03624261903151384 -0.05"/>
  </joint>
  <link name="disk_link_008">
    <contact>
        <lateral_friction value="1.0"/>
        <restitution value="0.0"/>
    </contact>
    <inertial>
      <origin rpy="0 0 0" xyz="0 0 0"/>
       <mass value="1.0"/>
       <inertia ixx="0" ixy="0" ixz="0" iyy="0" iyz="0" izz="0"/>
    </inertial>
    <collision>
      <origin rpy="0 0 0" xyz="0 0 0"/>
      <geometry>
        <box size="0.1 0.1 0.1"/>
      </geometry>
      <material name="white">
        <color rgba="1 1 1 1"/>
      </material>
    </collision>
    <visual>
      <origin rpy="0 0 0" xyz="0 0 0"/>
      <geometry>
        <box size="0.1 0.1 0.1"/>
      </geometry>
      <material name="white">
        <color rgba="1 1 1 1"/>
      </material>
    </visual>
  </link>
  <joint name="disk_joint_009" type="prismatic">
    <parent link="planeLink"/>
    <child link="disk_link_009"/>
    <limit effort="1000" lower="-10" upper="10" velocity="100000"/>
    <axis xyz="0 0 1"/>
    <origin rpy="0 0 0" xyz="0.9261747110678863 -0.2103429138079964 -0.05"/>
  </joint>
  <link name="disk_link_009">
    <contact>
        <lateral_friction value="1.0"/>
        <restitution value="0.0"/>
    </contact>
    <inertial>
      <origin rpy="0 0 0" xyz="0 0 0"/>
       <mass value="1.0"/>
       <inertia ixx="0" ixy="0" ixz="0" iyy="0" iyz="0" izz="0"/>
    </inertial>
    <collision>
      <origin rpy="0 0 0" xyz="0 0 0"/>
      <geometry>
        <box size="0.1 0.1 0.1"/>
      </geometry>
      <material name="white">
        <color rgba="1 1 1 1"/>
      </material>
    </collision>
    <visual>
      <origin rpy="0 0 0" xyz="0 0 0"/>
      <geometry>
        <box size="0.1 0.1 0.1"/>
      </geometry>
      <material name="white">
        <color rgba="1 1 1 1"/>
      </material>
    </visual>
  </link>
  <joint name="disk_joint_010" type="prismatic">
    <parent link="planeLink"/>
    <child link="disk_link_010"/>
    <limit effort="1000" lower="-10" upper="10" velocity="100000"/>
    <axis xyz="0 0 1"/>
    <origin rpy="0 0 0" xyz="0.9786134960198914 -0.04416917651523282 -0.05"/>
  </joint>
  <link name="disk_link_010">
    <contact>
        <lateral_friction value="1.0"/>
        <restitution value="0.0"/>
    </contact>
    <inertial>
      <origin rpy="0 0 0" xyz="0 0 0"/>
       <mass value="1.0"/>
       <inertia ixx="0" ixy="0" ixz="0" iyy="0" iyz="0" izz="0"/>
    </inertial>
    <collision>
      <origin rpy="0 0 0" xyz="0 0 0"/>
      <geometry>
        <box size="0.1 0.1 0.1"/>
      </geometry>
      <material name="white">
        <color rgba="1 1 1 1"/>
      </material>
    </collision>
    <visual>
      <origin rpy="0 0 0" xyz="0 0 0"/>
      <geometry>
        <box size="0.1 0.1 0.1"/>
      </geometry>
      <material name="white">
        <color rgba="1 1 1 1"/>
      </material>
    </visual>
  </link>
  <joint name="disk_joint_011" type="prismatic">
    <parent link="planeLink"/>
    <child link="disk_link_011"/>
    <limit effort="1000" lower="-10" upper="10" velocity="100000"/>
    <axis xyz="0 0 1"/>
    <origin rpy="0 0 0" xyz="1.0854353063743574 -0.22434633480902516 -0.05"/>
  </joint>
  <link name="disk_link_011">
    <contact>
        <lateral_friction value="1.0"/>
        <restitution value="0.0"/>
    </contact>
    <inertial>
      <origin rpy="0 0 0" xyz="0 0 0"/>
       <mass value="1.0"/>
       <inertia ixx="0" ixy="0" ixz="0" iyy="0" iyz="0" izz="0"/>
    </inertial>
    <collision>
      <origin rpy="0 0 0" xyz="0 0 0"/>
      <geometry>
        <box size="0.1 0.1 0.1"/>
      </geometry>
      <material name="white">
        <color rgba="1 1 1 1"/>
      </material>
    </collision>
    <visual>
      <origin rpy="0 0 0" xyz="0 0 0"/>
      <geometry>
        <box size="0.1 0.1 0.1"/>
      </geometry>
      <material name="white">
        <color rgba="1 1 1 1"/>
      </material>
    </visual>
  </link>
  <joint name="disk_joint_012" type="prismatic">
    <parent link="planeLink"/>
    <child link="disk_link_012"/>
    <limit effort="1000" lower="-10" upper="10" velocity="100000"/>
    <axis xyz="0 0 1"/>
    <origin rpy="0 0 0" xyz="1.129101384303726 -0.06329165956889105 -0.05"/>
  </joint>
  <link name="disk_link_012">
    <contact>
        <lateral_friction value="1.0"/>
        <restitution value="0.0"/>
    </contact>
    <inertial>
      <origin rpy="0 0 0" xyz="0 0 0"/>
       <mass value="1.0"/>
       <inertia ixx="0" ixy="0" ixz="0" iyy="0" iyz="0" izz="0"/>
    </inertial>
    <collision>
      <origin rpy="0 0 0" xyz="0 0 0"/>
      <geometry>
        <box size="0.1 0.1 0.1"/>
      </geometry>
      <material name="white">
        <color rgba="1 1 1 1"/>
      </material>
    </collision>
    <visual>
      <origin rpy="0 0 0" xyz="0 0 0"/>
      <geometry>
        <box size="0.1 0.1 0.1"/>
      </geometry>
      <material name="white">
        <color rgba="1 1 1 1"/>
      </material>
    </visual>
  </link>
  <joint name="disk_joint_013" type="prismatic">
    <parent link="planeLink"/>
    <child link="disk_link_013"/>
    <limit effort="1000" lower="-10" upper="10" velocity="100000"/>
    <axis xyz="0 0 1"/>
    <origin rpy="0 0 0" xyz="1.2167957033746286 -0.23983165702741302 -0.05"/>
  </joint>
  <link name="disk_link_013">
    <contact>
        <lateral_friction value="1.0"/>
        <restitution value="0.0"/>
    </contact>
    <inertial>
      <origin rpy="0 0 0" xyz="0 0 0"/>
       <mass value="1.0"/>
       <inertia ixx="0" ixy="0" ixz="0" iyy="0" iyz="0" izz="0"/>
    </inertial>
    <collision>
      <origin rpy="0 0 0" xyz="0 0 0"/>
      <geometry>
        <box size="0.1 0.1 0.1"/>
      </geometry>
      <material name="white">
        <color rgba="1 1 1 1"/>
      </material>
    </collision>
    <visual>
      <origin rpy="0 0 0" xyz="0 0 0"/>
      <geometry>
        <box size="0.1 0.1 0.1"/>
      </geometry>
      <material name="white">
        <color rgba="1 1 1 1"/>
      </material>
    </visual>
  </link>
  <joint name="disk_joint_014" type="prismatic">
    <parent link="planeLink"/>
    <child link="disk_link_014"/>
    <limit effort="1000" lower="-10" upper="10" velocity="100000"/>
    <axis xyz="0 0 1"/>
    <origin rpy="0 0 0" xyz="1.2715355927494527 -0.0754524941432633 -0.05"/>
  </joint>
  <link name="disk_link_014">
    <contact>
        <lateral_friction value="1.0"/>
        <restitution value="0.0"/>
    </contact>
    <inertial>
      <origin rpy="0 0 0" xyz="0 0 0"/>
       <mass value="1.0"/>
       <inertia ixx="0" ixy="0" ixz="0" iyy="0" iyz="0" izz="0"/>
    </inertial>
    <collision>
      <origin rpy="0 0 0" xyz="0 0 0"/>
      <geometry>
        <box size="0.1 0.1 0.1"/>
      </geometry>
      <material name="white">
        <color rgba="1 1 1 1"/>
      </material>
    </collision>
    <visual>
      <origin rpy="0 0 0" xyz="0 0 0"/>
      <geometry>
        <box size="0.1 0.1 0.1"/>
      </geometry>
      <material name="white">
        <color rgba="1 1 1 1"/>
      </material>
    </visual>
  </link>
  <joint name="disk_joint_015" type="prismatic">
    <parent link="planeLink"/>
    <child link="disk_link_015"/>
    <limit effort="1000" lower="-10" upper="10" velocity="100000"/>
    <axis xyz="0 0 1"/>
    <origin rpy="0 0 0" xyz="1.3730383763141698 -0.26609409071287693 -0.05"/>
  </joint>
  <link name="disk_link_015">
    <contact>
        <lateral_friction value="1.0"/>
        <restitution value="0.0"/>
    </contact>
    <inertial>
      <origin rpy="0 0 0" xyz="0 0 0"/>
       <mass value="1.0"/>
       <inertia ixx="0" ixy="0" ixz="0" iyy="0" iyz="0" izz="0"/>
    </inertial>
    <collision>
      <origin rpy="0 0 0" xyz="0 0 0"/>
      <geometry>
        <box size="0.1 0.1 0.1"/>
      </geometry>
      <material name="white">
        <color rgba="1 1 1 1"/>
      </material>
    </collision>
    <visual>
      <origin rpy="0 0 0" xyz="0 0 0"/>
      <geometry>
        <box size="0.1 0.1 0.1"/>
      </geometry>
      <material name="white">
        <color rgba="1 1 1 1"/>
      </material>
    </visual>
  </link>
  <joint name="disk_joint_016" type="prismatic">
    <parent link="planeLink"/>
    <child link="disk_link_016"/>
    <limit effort="1000" lower="-10" upper="10" velocity="100000"/>
    <axis xyz="0 0 1"/>
    <origin rpy="0 0 0" xyz="1.4168669954673883 -0.1030916474282379 -0.05"/>
  </joint>
  <link name="disk_link_016">
    <contact>
        <lateral_friction value="1.0"/>
        <restitution value="0.0"/>
    </contact>
    <inertial>
      <origin rpy="0 0 0" xyz="0 0 0"/>
       <mass value="1.0"/>
       <inertia ixx="0" ixy="0" ixz="0" iyy="0" iyz="0" izz="0"/>
    </inertial>
    <collision>
      <origin rpy="0 0 0" xyz="0 0 0"/>
      <geometry>
        <box size="0.1 0.1 0.1"/>
      </geometry>
      <material name="white">
        <color rgba="1 1 1 1"/>
      </material>
    </collision>
    <visual>
      <origin rpy="0 0 0" xyz="0 0 0"/>
      <geometry>
        <box size="0.1 0.1 0.1"/>
      </geometry>
      <material name="white">
        <color rgba="1 1 1 1"/>
      </material>
    </visual>
  </link>
  <joint name="disk_joint_017" type="prismatic">
    <parent link="planeLink"/>
    <child link="disk_link_017"/>
    <limit effort="1000" lower="-10" upper="10" velocity="100000"/>
    <axis xyz="0 0 1"/>
    <origin rpy="0 0 0" xyz="1.4961198844295418 -0.2948803547274615 -0.05"/>
  </joint>
  <link name="disk_link_017">
    <contact>
        <lateral_friction value="1.0"/>
        <restitution value="0.0"/>
    </contact>
    <inertial>
      <origin rpy="0 0 0" xyz="0 0 0"/>
       <mass value="1.0"/>
       <inertia ixx="0" ixy="0" ixz="0" iyy="0" iyz="0" izz="0"/>
    </inertial>
    <collision>
      <origin rpy="0 0 0" xyz="0 0 0"/>
      <geometry>
        <box size="0.1 0.1 0.1"/>
      </geometry>
      <material name="white">
        <color rgba="1 1 1 1"/>
      </material>
    </collision>
    <visual>
      <origin rpy="0 0 0" xyz="0 0 0"/>
      <geometry>
        <box size="0.1 0.1 0.1"/>
      </geometry>
      <material name="white">
        <color rgba="1 1 1 1"/>
      </material>
    </visual>
  </link>
  <joint name="disk_joint_018" type="prismatic">
    <parent link="planeLink"/>
    <child link="disk_link_018"/>
    <limit effort="1000" lower="-10" upper="10" velocity="100000"/>
    <axis xyz="0 0 1"/>
    <origin rpy="0 0 0" xyz="1.5699097740742016 -0.14001511267700847 -0.05"/>
  </joint>
  <link name="disk_link_018">
    <contact>
        <lateral_friction value="1.0"/>
        <restitution value="0.0"/>
    </contact>
    <inertial>
      <origin rpy="0 0 0" xyz="0 0 0"/>
       <mass value="1.0"/>
       <inertia ixx="0" ixy="0" ixz="0" iyy="0" iyz="0" izz="0"/>
    </inertial>
    <collision>
      <origin rpy="0 0 0" xyz="0 0 0"/>
      <geometry>
        <box size="0.1 0.1 0.1"/>
      </geometry>
      <material name="white">
        <color rgba="1 1 1 1"/>
      </material>
    </collision>
    <visual>
      <origin rpy="0 0 0" xyz="0 0 0"/>
      <geometry>
        <box size="0.1 0.1 0.1"/>
      </geometry>
      <material name="white">
        <color rgba="1 1 1 1"/>
      </material>
    </visual>
  </link>
  <joint name="disk_joint_019" type="prismatic">
    <parent link="planeLink"/>
    <child link="disk_link_019"/>
    <limit effort="1000" lower="-10" upper="10" velocity="100000"/>
    <axis xyz="0 0 1"/>
    <origin rpy="0 0 0" xyz="1.6365917712702216 -0.31507755066190846 -0.05"/>
  </joint>
  <link name="disk_link_019">
    <contact>
        <lateral_friction value="1.0"/>
        <restitution value="0.0"/>
    </contact>
    <inertial>
      <origin rpy="0 0 0" xyz="0 0 0"/>
       <mass value="1.0"/>
       <inertia ixx="0" ixy="0" ixz="0" iyy="0" iyz="0" izz="0"/>
    </inertial>
    <collision>
      <origin rpy="0 0 0" xyz="0 0 0"/>
      <geometry>
        <box size="0.1 0.1 0.1"/>
      </geometry>
      <material name="white">
        <color rgba="1 1 1 1"/>
      </material>
    </collision>
    <visual>
      <origin rpy="0 0 0" xyz="0 0 0"/>
      <geometry>
        <box size="0.1 0.1 0.1"/>
      </geometry>
      <material name="white">
        <color rgba="1 1 1 1"/>
      </material>
    </visual>
  </link>
  <joint name="disk_joint_020" type="prismatic">
    <parent link="planeLink"/>
    <child link="disk_link_020"/>
    <limit effort="1000" lower="-10" upper="10" velocity="100000"/>
    <axis xyz="0 0 1"/>
    <origin rpy="0 0 0" xyz="1.70755544799909 -0.15789058598035208 -0.05"/>
  </joint>
  <link name="disk_link_020">
    <contact>
        <lateral_friction value="1.0"/>
        <restitution value="0.0"/>
    </contact>
    <inertial>
      <origin rpy="0 0 0" xyz="0 0 0"/>
       <mass value="1.0"/>
       <inertia ixx="0" ixy="0" ixz="0" iyy="0" iyz="0" izz="0"/>
    </inertial>
    <collision>
      <origin rpy="0 0 0" xyz="0 0 0"/>
      <geometry>
        <box size="0.1 0.1 0.1"/>
      </geometry>
      <material name="white">
        <color rgba="1 1 1 1"/>
      </material>
    </collision>
    <visual>
      <origin rpy="0 0 0" xyz="0 0 0"/>
      <geometry>
        <box size="0.1 0.1 0.1"/>
      </geometry>
      <material name="white">
        <color rgba="1 1 1 1"/>
      </material>
    </visual>
  </link>
  <joint name="disk_joint_021" type="prismatic">
    <parent link="planeLink"/>
    <child link="disk_link_021"/>
    <limit effort="1000" lower="-10" upper="10" velocity="100000"/>
    <axis xyz="0 0 1"/>
    <origin rpy="0 0 0" xyz="1.7603258364441836 -0.34425680873397413 -0.05"/>
  </joint>
  <link name="disk_link_021">
    <contact>
        <lateral_friction value="1.0"/>
        <restitution value="0.0"/>
    </contact>
    <inertial>
      <origin rpy="0 0 0" xyz="0 0 0"/>
       <mass value="1.0"/>
       <inertia ixx="0" ixy="0" ixz="0" iyy="0" iyz="0" izz="0"/>
    </inertial>
    <collision>
      <origin rpy="0 0 0" xyz="0 0 0"/>
      <geometry>
        <box size="0.1 0.1 0.1"/>
      </geometry>
      <material name="white">
        <color rgba="1 1 1 1"/>
      </material>
    </collision>
    <visual>
      <origin rpy="0 0 0" xyz="0 0 0"/>
      <geometry>
        <box size="0.1 0.1 0.1"/>
      </geometry>
      <material name="white">
        <color rgba="1 1 1 1"/>
      </material>
    </visual>
  </link>
  <joint name="disk_joint_022" type="prismatic">
    <parent link="planeLink"/>
    <child link="disk_link_022"/>
    <limit effort="1000" lower="-10" upper="10" velocity="100000"/>
    <axis xyz="0 0 1"/>
    <origin rpy="0 0 0" xyz="1.8631400464074372 -0.2091863987519937 -0.05"/>
  </joint>
  <link name="disk_link_022">
    <contact>
        <lateral_friction value="1.0"/>
        <restitution value="0.0"/>
    </contact>
    <inertial>
      <origin rpy="0 0 0" xyz="0 0 0"/>
       <mass value="1.0"/>
       <inertia ixx="0" ixy="0" ixz="0" iyy="0" iyz="0" izz="0"/>
    </inertial>
    <collision>
      <origin rpy="0 0 0" xyz="0 0 0"/>
      <geometry>
        <box size="0.1 0.1 0.1"/>
      </geometry>
      <material name="white">
        <color rgba="1 1 1 1"/>
      </material>
    </collision>
    <visual>
      <origin rpy="0 0 0" xyz="0 0 0"/>
      <geometry>
        <box size="0.1 0.1 0.1"/>
      </geometry>
      <material name="white">
        <color rgba="1 1 1 1"/>
      </material>
    </visual>
  </link>
  <joint name="disk_joint_023" type="prismatic">
    <parent link="planeLink"/>
    <child link="disk_link_023"/>
    <limit effort="1000" lower="-10" upper="10" velocity="100000"/>
    <axis xyz="0 0 1"/>
    <origin rpy="0 0 0" xyz="1.9204584937315705 -0.39843645956395807 -0.05"/>
  </joint>
  <link name="disk_link_023">
    <contact>
        <lateral_friction value="1.0"/>
        <restitution value="0.0"/>
    </contact>
    <inertial>
      <origin rpy="0 0 0" xyz="0 0 0"/>
       <mass value="1.0"/>
       <inertia ixx="0" ixy="0" ixz="0" iyy="0" iyz="0" izz="0"/>
    </inertial>
    <collision>
      <origin rpy="0 0 0" xyz="0 0 0"/>
      <geometry>
        <box size="0.1 0.1 0.1"/>
      </geometry>
      <material name="white">
        <color rgba="1 1 1 1"/>
      </material>
    </collision>
    <visual>
      <origin rpy="0 0 0" xyz="0 0 0"/>
      <geometry>
        <box size="0.1 0.1 0.1"/>
      </geometry>
      <material name="white">
        <color rgba="1 1 1 1"/>
      </material>
    </visual>
  </link>
  <joint name="disk_joint_024" type="prismatic">
    <parent link="planeLink"/>
    <child link="disk_link_024"/>
    <limit effort="1000" lower="-10" upper="10" velocity="100000"/>
    <axis xyz="0 0 1"/>
    <origin rpy="0 0 0" xyz="2.0127336864782444 -0.2599968164636447 -0.05"/>
  </joint>
  <link name="disk_link_024">
    <contact>
        <lateral_friction value="1.0"/>
        <restitution value="0.0"/>
    </contact>
    <inertial>
      <origin rpy="0 0 0" xyz="0 0 0"/>
       <mass value="1.0"/>
       <inertia ixx="0" ixy="0" ixz="0" iyy="0" iyz="0" izz="0"/>
    </inertial>
    <collision>
      <origin rpy="0 0 0" xyz="0 0 0"/>
      <geometry>
        <box size="0.1 0.1 0.1"/>
      </geometry>
      <material name="white">
        <color rgba="1 1 1 1"/>
      </material>
    </collision>
    <visual>
      <origin rpy="0 0 0" xyz="0 0 0"/>
      <geometry>
        <box size="0.1 0.1 0.1"/>
      </geometry>
      <material name="white">
        <color rgba="1 1 1 1"/>
      </material>
    </visual>
  </link>
  <joint name="disk_joint_025" type="prismatic">
    <parent link="planeLink"/>
    <child link="disk_link_025"/>
    <limit effort="1000" lower="-10" upper="10" velocity="100000"/>
    <axis xyz="0 0 1"/>
    <origin rpy="0 0 0" xyz="1.9543735216764637 -0.38717488716160725 -0.05"/>
  </joint>
  <link name="disk_link_025">
    <contact>
        <lateral_friction value="1.0"/>
        <restitution value="0.0"/>
    </contact>
    <inertial>
      <origin rpy="0 0 0" xyz="0 0 0"/>
       <mass value="1.0"/>
       <inertia ixx="0" ixy="0" ixz="0" iyy="0" iyz="0" izz="0"/>
    </inertial>
    <collision>
      <origin rpy="0 0 0" xyz="0 0 0"/>
      <geometry>
        <box size="0.1 0.1 0.1"/>
      </geometry>
      <material name="white">
        <color rgba="1 1 1 1"/>
      </material>
    </collision>
    <visual>
      <origin rpy="0 0 0" xyz="0 0 0"/>
      <geometry>
        <box size="0.1 0.1 0.1"/>
      </geometry>
      <material name="white">
        <color rgba="1 1 1 1"/>
      </material>
    </visual>
  </link>
  <joint name="disk_joint_026" type="prismatic">
    <parent link="planeLink"/>
    <child link="disk_link_026"/>
    <limit effort="1000" lower="-10" upper="10" velocity="100000"/>
    <axis xyz="0 0 1"/>
    <origin rpy="0 0 0" xyz="2.041939873253766 -0.4280686786705801 -0.05"/>
  </joint>
  <link name="disk_link_026">
    <contact>
        <lateral_friction value="1.0"/>
        <restitution value="0.0"/>
    </contact>
    <inertial>
      <origin rpy="0 0 0" xyz="0 0 0"/>
       <mass value="1.0"/>
       <inertia ixx="0" ixy="0" ixz="0" iyy="0" iyz="0" izz="0"/>
    </inertial>
    <collision>
      <origin rpy="0 0 0" xyz="0 0 0"/>
      <geometry>
        <box size="0.1 0.1 0.1"/>
      </geometry>
      <material name="white">
        <color rgba="1 1 1 1"/>
      </material>
    </collision>
    <visual>
      <origin rpy="0 0 0" xyz="0 0 0"/>
      <geometry>
        <box size="0.1 0.1 0.1"/>
      </geometry>
      <material name="white">
        <color rgba="1 1 1 1"/>
      </material>
    </visual>
  </link>

</robot>
