<?xml version="1.0" ?>
<robot name="plane">
  <link name="world"/>
  <joint name="fixed_joint" type="fixed">
    <parent link="world"/>
    <child link="root"/>
  </joint>
  <link name="root"/>
  <joint name="surface_joint" type="prismatic">
    <parent link="root"/>
    <child link="surface_link"/>
    <limit effort="1000" lower="-10" upper="10" velocity="100000"/>
    <axis xyz="0 0 1"/>
    <origin rpy="0 0 0" xyz="0 0 0"/>
  </joint>
  <link name="surface_link">
    <contact>
        <lateral_friction value="0.0"/>
        <restitution value="0.0"/>
    </contact>
    <inertial>
      <origin rpy="0 0 0" xyz="0 0 0"/>
       <mass value="1.0"/>
       <inertia ixx="0" ixy="0" ixz="0" iyy="0" iyz="0" izz="0"/>
    </inertial>
    <visual>
      <origin rpy="0 0 0" xyz="0 0 0"/>
      <geometry>
      <box size="0.5 0.5 0.005"/>
      </geometry>
       <material name="white">
        <color rgba="1 1 1 1"/>
      </material>
    </visual>
    <collision>
      <origin rpy="0 0 0" xyz="0 0 0"/>
      <geometry>
      <box size="0.5 0.5 0.005"/>
      </geometry>
    </collision>
  </link>
</robot>